File: pages/KSeV1Rand.xrdml
<?xml version="1.0" encoding="utf-8" standalone="no"?>
<xrdMeasurements xmlns="http://www.xrdml.com/XRDMeasurement/1.0" xmlns:xsi="http://www.w3.org/2001/XMLSchema-instance" xsi:schemaLocation="http://www.xrdml.com/XRDMeasurement/1.3 http://www.xrdml.com/XRDMeasurement/1.3/XRDMeasurement.xsd" status="Completed">
  <sample type="To be analyzed">
    <id>000000-0000 - Converted with PowDLL</id>
    <name>KSeV1Rand</name>
  </sample>
  <xrdMeasurement measurementType="Scan" status="Completed">
    <usedWavelength intended="K-Alpha">
      <kAlpha1 unit="Angstrom">1,5406</kAlpha1>
      <kAlpha2 unit="Angstrom">1,54439</kAlpha2>
      <kBeta unit="Angstrom">1.3922500</kBeta>
      <ratioKAlpha2KAlpha1>0,5</ratioKAlpha2KAlpha1>
    </usedWavelength>
    <!--KBeta value not accurate but needed by the xrdml format. Please change.-->
    <incidentBeamPath>
      <radius unit="mm">200,5</radius>
    </incidentBeamPath>
    <diffractedBeamPath>
      <radius unit="mm">200,5</radius>
    </diffractedBeamPath>
    <scan appendNumber="0" mode="Continuous" scanAxis="Gonio" status="Completed">
      <header>
        <startTimeStamp>2020-03-13T16:44:54+00:00</startTimeStamp>
        <endTimeStamp>2020-03-13T16:44:54+00:00</endTimeStamp>
        <!--Time/Date values are not accurate but needed by the xrdml format-->
        <author>
          <name>PowDLL</name>
        </author>
        <source>
          <applicationSoftware version="2.34">PowDLL</applicationSoftware>
        </source>
      </header>
      <dataPoints>
        <positions axis="2Theta" unit="deg">
          <startPosition>5</startPosition>
          <endPosition>80,00</endPosition>
        </positions>
        <commonCountingTime unit="seconds">4,99973</commonCountingTime>
        <intensities unit="counts">55 40 53 57 58 38 48 58 51 49 48 53 41 34 54 53 40 55 50 50 47 67 58 50 46 46 48 47 48 43 54 49 41 55 35 31 33 59 51 38 61 35 33 52 37 35 46 37 46 32 44 33 34 33 38 39 52 36 45 48 34 45 41 43 40 37 47 38 39 41 37 37 29 41 51 45 33 38 37 34 38 33 40 38 31 38 36 32 35 32 34 61 42 33 36 39 40 34 38 30 37 25 41 31 30 30 24 40 42 35 26 31 43 35 34 24 34 38 24 31 36 35 39 35 34 39 44 42 41 39 27 36 37 41 44 46 46 37 53 48 63 54 52 75 70 47 49 56 40 26 38 42 37 33 39 46 42 29 21 25 32 39 26 39 25 33 30 34 30 38 29 24 32 25 15 27 19 30 29 27 19 32 23 30 29 35 21 32 31 29 28 34 30 29 32 24 35 29 27 24 31 30 22 33 31 22 31 30 21 27 19 19 29 33 27 21 27 24 24 27 16 23 24 32 23 29 24 15 17 34 25 32 27 31 16 21 35 24 28 14 20 19 36 22 32 26 20 24 23 26 27 23 31 30 26 30 30 24 20 25 28 22 28 19 26 18 19 22 23 22 21 25 21 21 19 24 25 15 34 27 18 23 30 21 19 19 25 25 28 28 16 18 24 20 18 16 18 11 26 31 26 25 25 17 14 13 16 21 19 10 22 18 10 20 19 23 14 20 22 22 24 17 22 17 23 22 26 26 23 16 32 15 13 29 18 17 21 14 23 18 24 16 26 23 21 26 20 21 12 17 16 19 22 22 27 18 19 11 25 18 20 21 20 22 20 22 26 14 15 23 20 10 26 20 14 17 18 21 25 23 20 24 20 13 26 20 23 20 21 19 26 22 20 16 15 24 22 12 14 20 16 19 22 17 26 19 16 33 19 15 18 22 13 20 24 16 23 25 28 19 21 11 17 24 19 19 26 25 21 13 18 26 25 18 19 14 26 19 30 25 30 19 18 19 21 22 19 23 26 24 19 14 26 19 18 19 15 20 17 16 18 17 18 16 28 29 22 20 15 20 20 21 14 22 18 21 19 21 17 26 15 29 19 31 18 17 18 15 13 19 20 26 20 22 29 18 22 15 31 17 22 20 22 20 12 14 23 21 16 24 14 12 24 19 18 18 23 21 13 22 27 13 25 14 19 25 13 26 19 15 23 30 21 28 17 18 15 21 22 30 24 20 26 21 17 19 19 21 23 17 24 22 23 24 22 18 16 26 29 26 31 27 23 31 25 32 23 30 27 22 19 15 27 26 17 28 23 19 22 29 19 31 33 19 16 25 24 17 20 18 15 24 23 18 24 20 19 26 14 23 32 21 20 25 10 13 23 17 31 22 29 24 19 19 14 19 23 23 26 29 18 25 24 20 24 24 13 22 26 18 30 14 29 14 21 15 16 19 26 18 20 14 21 19 28 14 21 17 27 18 13 14 18 24 26 28 20 26 15 16 17 18 18 23 17 18 19 17 20 15 28 23 25 26 15 12 20 23 21 20 20 15 14 11 18 21 16 18 25 24 19 23 19 18 16 16 26 17 20 20 20 25 17 19 18 19 26 17 16 14 27 20 16 17 16 17 16 19 15 16 21 22 23 19 17 26 23 18 16 17 25 28 17 23 17 23 22 21 15 35 28 16 19 26 18 15 22 13 18 20 22 15 24 20 24 26 22 21 14 22 24 19 27 19 29 22 30 23 16 21 29 36 33 38 44 30 44 52 48 46 44 45 67 70 87 105 146 228 370 641 1090 1487 1656 1260 870 600 296 152 104 66 51 57 45 48 38 45 44 33 26 23 29 18 16 14 18 19 18 24 25 24 30 16 12 28 23 23 23 25 22 16 26 21 22 18 19 23 23 27 25 20 11 30 22 24 23 20 11 24 21 25 22 16 16 18 30 27 14 20 28 24 22 18 18 24 27 23 23 24 20 28 26 31 21 22 22 14 24 25 25 26 28 27 23 26 22 20 17 24 23 24 19 18 22 23 13 13 18 28 34 22 25 21 27 20 28 29 31 29 27 25 24 26 27 25 40 18 34 23 16 29 31 31 24 18 26 23 26 33 30 41 39 26 21 21 26 25 22 24 26 29 31 23 21 25 21 23 38 24 29 31 12 35 22 26 19 35 22 27 22 28 28 32 23 22 31 29 24 35 36 27 38 24 28 22 25 30 31 27 27 28 21 20 17 27 30 33 31 34 30 25 28 21 32 28 32 25 22 34 26 32 23 31 35 34 23 27 28 31 31 25 35 30 23 32 34 32 31 30 34 50 36 29 33 25 35 36 39 36 36 46 45 36 38 34 24 36 32 40 38 40 29 31 46 35 32 37 43 45 48 41 28 51 57 63 59 59 63 81 86 81 125 131 146 147 156 159 180 162 195 221 240 260 335 416 580 860 1306 1872 2939 4960 8816 11501 12069 10391 7320 5937 4566 2157 805 445 340 285 228 254 213 167 149 138 129 99 99 100 91 87 69 74 82 52 79 63 72 64 54 53 58 66 50 58 58 54 57 68 62 50 65 48 44 44 36 41 49 37 37 46 28 39 44 31 37 41 49 32 24 37 37 45 38 29 36 29 32 46 43 33 42 32 29 38 45 46 38 40 45 27 40 39 41 39 44 35 39 42 41 22 33 44 45 33 32 38 36 37 55 49 56 51 57 46 53 54 71 82 84 86 91 99 96 113 87 77 73 59 78 65 65 54 54 64 61 63 56 57 60 71 61 66 67 82 88 94 83 61 72 69 68 54 63 45 62 54 45 50 47 62 50 53 57 53 45 66 44 54 55 62 66 60 60 58 65 57 59 64 55 57 54 56 53 48 56 52 55 51 56 54 35 46 35 42 37 35 33 32 28 44 41 33 42 28 38 34 39 34 58 43 38 40 32 40 34 48 30 42 31 34 26 37 29 25 28 35 36 28 33 41 50 23 41 22 32 31 35 38 35 25 41 30 18 42 26 26 35 36 36 40 37 38 41 50 36 32 19 39 34 38 47 54 47 48 41 52 47 54 49 39 47 43 35 34 40 38 33 30 48 36 29 33 43 33 29 32 23 32 23 22 43 32 22 32 38 30 30 33 26 38 25 30 38 37 31 36 24 32 32 33 27 38 33 39 33 32 33 32 39 34 34 34 37 31 39 36 48 40 35 51 34 51 47 50 45 39 31 35 31 44 32 31 34 30 33 24 28 17 41 35 25 17 33 35 23 21 27 23 20 21 28 22 16 16 22 21 27 21 14 22 22 18 16 26 16 21 18 24 22 27 32 34 24 32 25 28 23 17 33 27 26 27 21 19 21 22 28 29 25 18 20 20 14 24 28 21 22 24 24 19 22 14 17 23 21 22 17 25 33 21 21 19 23 22 22 25 21 27 26 32 26 15 25 27 29 30 25 24 23 31 25 28 28 21 20 25 16 28 18 20 25 27 27 27 22 23 22 22 29 34 31 27 31 33 25 26 25 28 21 19 28 28 24 26 34 28 35 40 38 42 48 25 35 38 29 39 32 42 47 44 33 49 38 55 65 83 67 71 143 195 277 358 348 272 220 218 186 173 112 74 51 47 38 31 26 25 32 31 25 18 26 25 28 20 35 17 20 29 28 18 28 27 20 34 25 31 28 23 27 17 23 22 13 30 32 28 24 20 24 18 30 29 25 32 21 25 25 30 24 25 25 36 30 24 19 26 26 34 26 36 34 38 34 31 37 17 31 32 25 28 22 31 25 24 29 18 25 25 20 24 26 29 25 31 31 29 32 30 35 31 33 35 35 24 42 31 29 32 29 30 33 24 22 18 19 23 20 22 18 18 27 18 28 32 21 23 37 31 35 27 34 24 24 28 31 29 41 46 29 49 51 48 73 122 146 186 241 397 455 333 228 204 223 249 180 85 63 50 25 39 41 38 33 39 27 26 26 21 23 23 31 35 38 25 34 23 39 34 25 28 31 33 38 36 62 79 118 148 200 249 230 139 115 122 114 111 71 57 27 33 35 25 18 23 32 17 16 28 24 23 21 15 18 16 33 15 20 19 26 15 14 20 24 24 18 23 11 16 26 24 24 30 23 19 24 20 20 23 18 31 22 27 28 23 11 32 12 22 27 19 21 25 24 29 28 15 29 31 22 20 17 21 23 22 17 23 19 28 29 22 22 20 24 24 24 26 22 21 33 24 36 28 29 27 32 39 44 35 50 50 67 78 112 158 186 273 337 402 305 217 174 177 186 198 131 71 48 47 34 27 30 31 41 23 24 29 27 28 29 38 32 26 31 36 31 31 24 26 27 22 26 22 31 36 23 18 33 25 25 29 27 21 24 23 17 20 22 22 27 18 18 27 23 30 25 21 21 19 23 18 20 19 21 25 19 15 23 20 13 30 23 19 25 21 20 28 21 25 18 22 35 27 33 19 21 16 24 14 20 24 11 23 26 31 27 21 29 22 29 22 23 27 24 18 24 28 25 26 20 29 27 25 26 28 33 24 26 30 25 26 12 16 16 21 23 24 29 27 26 20 18 35 31 30 27 29 32 31 23 24 24 36 28 24 32 33 31 27 36 23 44 43 34 47 44 35 41 54 61 62 107 128 190 224 300 310 206 169 118 148 189 169 104 68 57 48 30 33 33 31 28 28 35 19 31 28 22 27 24 28 23 23 21 23 18 21 25 10 19 21 24 19 21 33 21 17 21 13 16 24 22 25 23 17 12 20 14 19 25 28 27 25 22 23 12 14 25 14 18 18 24 27 20 21 27 24 22 20 28 19 19 21 20 23 35 23 31 28 18 31 30 26 25 27 26 20 21 29 28 21 28 17 18 24 14 22 22 17 15 21 25 20 17 25 17 28 19 25 18 23 28 21 28 21 30 29 31 34 29 34 33 33 37 39 38 40 41 41 30 38 41 45 30 36 25 29 27 16 19 32 29 23 26 14 26 29 18 20 17 25 26 27 20 18 24 30 24 22 20 25 19 28 22 37 35 22 45 35 30 41 37 35 32 42 41 37 32 38 37 31 31 36 33 43 37 39 49 44 35 44 39 43 48 42 40 38 56 53 55 59 78 69 91 82 95 124 164 258 346 497 694 965 1033 778 470 361 320 454 524 492 329 155 113 58 52 48 43 41 43 38 39 29 35 47 38 42 67 56 40 29 38 32 24 33 24 36 27 24 27 30 26 32 29 19 24 27 28 22 27 18 23 21 28 22 18 19 29 25 21 18 19 17 18 25 22 19 29 25 29 20 21 19 24 23 15 33 21 19 25 16 25 11 14 16 25 21 20 27 22 23 23 15 25 20 23 18 16 17 20 22 23 15 24 21 20 15 11 21 21 26 26 25 19 27 25 26 25 25 30 30 23 24 19 24 23 29 21 25 15 24 17 32 27 28 30 25 19 19 32 20 19 27 21 18 32 22 28 22 30 19 23 14 21 19 23 18 19 22 24 29 19 15 17 25 20 14 18 17 14 20 13 14 17 12 16 18 18 16 13 22 11 26 26 19 16 24 15 21 23 22 16 11 15 12 22 20 16 19 13 18 21 25 29 24 16 12 11 26 27 14 17 20 30 21 17 19 14 23 19 18 25 28 31 18 26 27 31 40 39 36 42 49 54 66 91 112 155 231 304 297 222 131 121 87 125 137 241 159 85 63 46 38 32 32 39 48 38 55 71 101 119 130 93 82 47 48 68 58 70 71 48 32 34 25 22 20 20 29 14 16 27 14 35 27 25 21 25 22 26 15 20 27 25 19 21 13 19 19 21 12 18 30 26 24 24 21 19 23 21 17 17 21 25 15 22 18 28 24 20 19 18 18 20 18 19 23 21 14 13 13 19 11 21 21 14 22 19 14 17 23 12 15 14 14 20 19 19 19 14 20 20 20 20 28 21 36 34 23 20 34 31 21 29 25 30 26 21 22 22 17 25 23 18 22 18 31 14 17 21 13 18 14 20 12 18 20 13 17 14 16 17 18 21 20 18 17 17 17 20 21 24 8 14 16 17 23 22 18 28 16 19 19 19 20 18 24 12 5 18 12 27 6 23 14 20 14 22 11 15 27 20 24 20 19 16 24 12 20 18 11 22 24 17 21 17 15 10 23 27 25 14 21 14 20 18 16 18 17 26 17 13 19 19 26 19 24 12 25 25 24 23 23 34 26 22 26 30 33 32 39 55 39 54 62 62 89 95 124 141 200 259 386 491 504 404 261 161 168 180 236 259 272 215 133 96 59 39 33 25 45 29 28 28 26 24 35 21 22 31 19 16 22 16 18 15 23 17 16 26 17 17 26 29 29 21 26 22 20 18 21 18 15 23 18 17 15 18 13 20 15 18 19 12 18 19 20 10 17 17 22 11 15 19 21 12 19 18 21 21 16 16 15 12 22 19 18 15 12 22 15 14 18 15 24 23 18 22 20 16 13 20 16 14 15 14 22 16 14 14 19 15 11 25 15 13 16 9 14 11 15 19 9 10 23 10 13 15 13 10 14 9 10 15 14 18 13 22 11 21 9 15 18 16 24 12 11 12 14 14 22 18 18 14 14 16 15 9 14 14 14 15 19 20 17 16 20 12 16 17 21 11 18 16 20 19 18 14 11 19 12 23 14 22 15 25 21 21 14 13 13 13 23 21 19 20 25 19 21 29 27 33 28 53 57 74 110 111 74 84 46 39 38 50 59 59 55 49 27 31 28 21 15 18 20 16 27 11 16 15 19 21 18 20 26 18 18 22 14 19 21 15 27 27 25 18 22 16 13 17 21 19 17 19 20 21 15 20 17 15 20 19 23 16 16 20 19 9 25 19 14 18 14 18 11 21 19 18 26 22 18 16 24 21 19 21 25 17 30 29 22 26 25 35 27 45 34 23 21 24 22 18 26 23 21 19 22 23 22 12 16 16 20 20 18 18 19 18 16 16 18 19 22 26 23 8 22 25 21 23 17 16 18 18 20 13 13 14 22 29 14 18 21 14 20 21 16 15 19 25 20 16 18 17 14 16 20 13 21 22 21 22 27 11 24 15 15 15 21 21 27 14 26 22 18 25 25 28 33 14 35 36 42 45 56 75 89 108 128 166 236 270 391 334 287 211 144 134 118 136 133 166 198 199 148 122 110 112 148 163 212 283 356 367 346 266 205 199 239 302 355 338 346 303 216 141 102 99 141 145 118 126 103 73 72 50 36 28 25 23 23 32 24 24 22 20 21 16 19 22 26 18 22 20 23 18 11 26 13 21 19 19 14 23 14 16 13 14 7 15 17 16 18 17 17 16 23 16 12 17 11 12 16 22 12 16 16 15 13 15 16 20 21 20 13 11 16 10 17 19 19 20 10 18 10 16 13 18 17 12 26 26 18 17 18 15 11 15 14 17 12 13 15 21 14 13 12 15 15 16 14 26 13 9 10 10 14 13 12 13 19 14 16 22 10 14 11 12 12 23 18 15 16 14 11 20 14 11 22 12 17 15 10 14 13 15 13 15 16 15 22 21 8 15 14 5 14 19 14 13 14 13 20 9 14 6 16 23 18 17 14 16 19 23 18 13 19 11 12 15 11 8 13 16 10 22 14 13 16 13 12 10 13 11 13 14 9 12 13 17 15 11 10 15 15 16 9 12 12 19 15 12 10 23 13 13 14 20 19 14 9 9 8 16 11 17 12 21 8 19 14 16 16 18 18 9 9 15 13 17 22 20 13 11 17 13 21 15 15 21 21 30 38 38 47 48 75 85 98 106 82 78 45 35 39 33 28 49 50 50 47 36 39 30 19 16 16 13 24 16 20 11 19 21 20 26 19 7 9 12 22 17 19 11 13 6 10 15 13 14 10 11 13 14 8 11 18 17 19 13 14 13 16 19 14 15 10 22 14 10 16 18 14 18 17 23 24 19 18 11 10 10 18 16 19 16 15 13 13 18 20 16 13 21 13 21 21 21 17 16 23 21 19 19 22 28 27 20 27 24 31 32 56 59 75 84 98 137 119 128 105 85 53 54 51 54 62 71 66 81 70 54 43 32 28 24 28 11 23 25 19 16 23 13 17 20 16 11 16 16 15 25 20 20 17 18 19 19 15 17 16 18 15 18 21 14 19 17 20 12 13 14 15 16 19 16 15 17 22 14 13 14 18 13 20 22 18 15 8 21 22 18 19 19 14 19 18 12 22 17 20 12 10 23 10 13 16 16 22 23 23 26 24 34 36 45 39 47 47 61 53 40 37 23 31 37 29 20 36 41 39 38 33 22 25 18 16 18 23 18 13 13 19 16 18 13 15 23 13 16 14 17 17 16 13 19 12 13 16 13 17 13 15 13 15 22 15 9 20 7 12 12 19 10 14 15 14 14 15 17 17 16 17 21 23 14 11 13 11 12 18 18 19 11 15 16 28 21 17 15 22 16 18 16 22 23 21 15 17 15 20 21 26 29 27 23 25 27 25 22 27 42 47 45 62 68 110 87 122 137 139 120 92 81 64 67 68 77</intensities>
      </dataPoints>
    </scan>
  </xrdMeasurement>
</xrdMeasurements>