File: pages/SiGlas.xrdml
<?xml version="1.0" encoding="utf-8" standalone="no"?>
<xrdMeasurements xmlns="http://www.xrdml.com/XRDMeasurement/1.0" xmlns:xsi="http://www.w3.org/2001/XMLSchema-instance" xsi:schemaLocation="http://www.xrdml.com/XRDMeasurement/1.3 http://www.xrdml.com/XRDMeasurement/1.3/XRDMeasurement.xsd" status="Completed">
  <sample type="To be analyzed">
    <id>000000-0000 - Converted with PowDLL</id>
    <name>SiO2_50_Glas_50</name>
  </sample>
  <xrdMeasurement measurementType="Scan" status="Completed">
    <usedWavelength intended="K-Alpha">
      <kAlpha1 unit="Angstrom">1,5406</kAlpha1>
      <kAlpha2 unit="Angstrom">1,54439</kAlpha2>
      <kBeta unit="Angstrom">1.3922500</kBeta>
      <ratioKAlpha2KAlpha1>0,5</ratioKAlpha2KAlpha1>
    </usedWavelength>
    <!--KBeta value not accurate but needed by the xrdml format. Please change.-->
    <incidentBeamPath>
      <radius unit="mm">200,5</radius>
    </incidentBeamPath>
    <diffractedBeamPath>
      <radius unit="mm">200,5</radius>
    </diffractedBeamPath>
    <scan appendNumber="0" mode="Continuous" scanAxis="Gonio" status="Completed">
      <header>
        <startTimeStamp>2021-03-08T11:46:05+00:00</startTimeStamp>
        <endTimeStamp>2021-03-08T11:46:05+00:00</endTimeStamp>
        <!--Time/Date values are not accurate but needed by the xrdml format-->
        <author>
          <name>PowDLL</name>
        </author>
        <source>
          <applicationSoftware version="2.43">PowDLL</applicationSoftware>
        </source>
      </header>
      <dataPoints>
        <positions axis="2Theta" unit="deg">
          <startPosition>3,000</startPosition>
          <endPosition>74,840</endPosition>
        </positions>
        <commonCountingTime unit="seconds">14,9964</commonCountingTime>
        <intensities unit="counts">337,000 295,000 290,000 317,000 279,000 284,000 257,000 301,000 270,000 237,000 220,000 235,000 267,000 227,000 245,000 231,000 232,000 215,000 211,000 237,000 206,000 212,000 190,000 182,000 199,000 144,000 174,000 206,000 187,000 190,000 189,000 181,000 159,000 180,000 211,000 148,000 159,000 178,000 174,000 151,000 181,000 175,000 150,000 167,000 154,000 145,000 148,000 146,000 149,000 155,000 150,000 137,000 144,000 152,000 126,000 121,000 151,000 136,000 137,000 137,000 136,000 136,000 126,000 135,000 129,000 139,000 123,000 133,000 126,000 129,000 116,000 118,000 134,000 118,000 108,000 118,000 130,000 113,000 128,000 115,000 99,000 112,000 110,000 108,000 98,000 103,000 110,000 104,000 112,000 129,000 89,000 96,000 106,000 111,000 96,000 112,000 113,000 110,000 112,000 106,000 109,000 104,000 108,000 90,000 99,000 92,000 114,000 99,000 96,000 84,000 104,000 116,000 92,000 98,000 91,000 80,000 78,000 98,000 86,000 85,000 95,000 98,000 103,000 89,000 86,000 94,000 104,000 110,000 89,000 89,000 73,000 89,000 76,000 90,000 95,000 100,000 93,000 98,000 96,000 80,000 77,000 92,000 96,000 120,000 81,000 79,000 87,000 112,000 95,000 83,000 85,000 81,000 97,000 88,000 78,000 102,000 76,000 82,000 69,000 71,000 91,000 92,000 101,000 96,000 66,000 82,000 84,000 82,000 64,000 83,000 75,000 85,000 70,000 78,000 76,000 68,000 65,000 75,000 86,000 89,000 94,000 82,000 73,000 86,000 89,000 80,000 76,000 85,000 84,000 98,000 86,000 81,000 93,000 73,000 78,000 74,000 88,000 84,000 74,000 79,000 80,000 84,000 70,000 72,000 86,000 85,000 80,000 80,000 80,000 87,000 79,000 85,000 80,000 70,000 69,000 75,000 74,000 75,000 90,000 74,000 91,000 90,000 82,000 73,000 84,000 73,000 80,000 75,000 80,000 91,000 67,000 76,000 87,000 95,000 77,000 77,000 75,000 66,000 76,000 70,000 73,000 83,000 71,000 86,000 74,000 81,000 73,000 74,000 80,000 91,000 92,000 71,000 90,000 79,000 75,000 79,000 77,000 73,000 59,000 88,000 96,000 80,000 86,000 85,000 74,000 64,000 83,000 78,000 92,000 71,000 82,000 72,000 78,000 80,000 69,000 78,000 82,000 72,000 68,000 72,000 74,000 56,000 74,000 75,000 72,000 72,000 89,000 76,000 99,000 87,000 75,000 89,000 78,000 85,000 79,000 80,000 75,000 92,000 57,000 76,000 82,000 85,000 69,000 71,000 95,000 82,000 82,000 70,000 83,000 75,000 80,000 86,000 64,000 85,000 67,000 88,000 79,000 74,000 78,000 83,000 85,000 87,000 84,000 66,000 78,000 90,000 75,000 84,000 77,000 82,000 84,000 85,000 69,000 73,000 76,000 101,000 78,000 77,000 86,000 76,000 83,000 62,000 70,000 71,000 88,000 86,000 75,000 89,000 63,000 79,000 82,000 89,000 77,000 76,000 70,000 85,000 72,000 82,000 85,000 75,000 72,000 74,000 81,000 88,000 82,000 79,000 81,000 76,000 89,000 65,000 81,000 83,000 63,000 90,000 61,000 78,000 73,000 92,000 86,000 85,000 80,000 80,000 85,000 63,000 88,000 89,000 86,000 84,000 82,000 102,000 88,000 63,000 87,000 86,000 83,000 77,000 75,000 90,000 86,000 90,000 95,000 87,000 96,000 92,000 83,000 99,000 78,000 90,000 92,000 90,000 94,000 99,000 105,000 83,000 93,000 79,000 83,000 92,000 84,000 94,000 86,000 79,000 80,000 82,000 85,000 90,000 87,000 70,000 88,000 81,000 86,000 63,000 66,000 78,000 68,000 89,000 75,000 98,000 70,000 96,000 91,000 62,000 101,000 98,000 96,000 91,000 93,000 86,000 89,000 92,000 68,000 71,000 87,000 87,000 84,000 71,000 94,000 96,000 94,000 84,000 97,000 90,000 84,000 96,000 101,000 81,000 101,000 113,000 107,000 101,000 109,000 97,000 103,000 97,000 103,000 105,000 79,000 86,000 102,000 86,000 95,000 96,000 88,000 94,000 92,000 97,000 109,000 105,000 88,000 87,000 91,000 80,000 102,000 87,000 90,000 83,000 87,000 92,000 92,000 90,000 91,000 97,000 96,000 90,000 81,000 94,000 95,000 80,000 101,000 96,000 104,000 97,000 93,000 98,000 90,000 105,000 93,000 89,000 94,000 91,000 80,000 90,000 96,000 89,000 106,000 102,000 110,000 101,000 98,000 100,000 95,000 117,000 100,000 105,000 94,000 110,000 110,000 108,000 101,000 114,000 85,000 102,000 107,000 105,000 90,000 90,000 108,000 128,000 85,000 96,000 91,000 96,000 118,000 99,000 112,000 97,000 90,000 92,000 89,000 88,000 96,000 93,000 85,000 100,000 114,000 107,000 105,000 98,000 98,000 84,000 104,000 97,000 118,000 108,000 91,000 88,000 105,000 113,000 101,000 101,000 89,000 85,000 101,000 81,000 96,000 119,000 99,000 105,000 112,000 98,000 97,000 107,000 98,000 112,000 92,000 98,000 108,000 111,000 118,000 98,000 90,000 112,000 107,000 108,000 96,000 109,000 123,000 115,000 90,000 107,000 105,000 118,000 108,000 115,000 118,000 109,000 103,000 105,000 126,000 103,000 111,000 119,000 114,000 106,000 100,000 110,000 98,000 99,000 104,000 89,000 107,000 130,000 103,000 114,000 111,000 117,000 117,000 114,000 117,000 122,000 115,000 91,000 125,000 136,000 105,000 97,000 126,000 122,000 106,000 107,000 94,000 112,000 110,000 112,000 113,000 130,000 116,000 103,000 125,000 124,000 146,000 134,000 114,000 113,000 126,000 120,000 129,000 95,000 117,000 126,000 131,000 120,000 112,000 120,000 125,000 137,000 138,000 120,000 131,000 120,000 140,000 113,000 129,000 119,000 100,000 146,000 123,000 120,000 119,000 124,000 106,000 116,000 139,000 114,000 144,000 113,000 130,000 148,000 120,000 129,000 121,000 151,000 134,000 137,000 135,000 149,000 145,000 120,000 134,000 144,000 154,000 156,000 148,000 146,000 135,000 156,000 146,000 132,000 142,000 135,000 144,000 148,000 137,000 137,000 133,000 140,000 140,000 135,000 141,000 164,000 134,000 135,000 154,000 157,000 145,000 161,000 153,000 158,000 156,000 150,000 153,000 154,000 153,000 142,000 158,000 155,000 189,000 168,000 148,000 133,000 150,000 175,000 132,000 155,000 150,000 171,000 163,000 163,000 153,000 145,000 146,000 151,000 180,000 190,000 159,000 161,000 163,000 146,000 168,000 168,000 171,000 166,000 140,000 201,000 183,000 165,000 184,000 181,000 171,000 177,000 206,000 175,000 194,000 161,000 171,000 167,000 165,000 182,000 193,000 161,000 169,000 198,000 196,000 187,000 185,000 179,000 199,000 179,000 181,000 180,000 184,000 198,000 203,000 164,000 197,000 186,000 178,000 205,000 196,000 188,000 193,000 175,000 198,000 186,000 184,000 193,000 208,000 198,000 197,000 191,000 191,000 193,000 175,000 203,000 229,000 188,000 202,000 179,000 183,000 203,000 215,000 213,000 197,000 200,000 210,000 223,000 196,000 192,000 194,000 200,000 203,000 196,000 213,000 215,000 221,000 221,000 195,000 209,000 241,000 209,000 203,000 223,000 210,000 208,000 198,000 209,000 230,000 237,000 231,000 194,000 245,000 221,000 224,000 226,000 226,000 225,000 221,000 229,000 224,000 240,000 238,000 237,000 266,000 244,000 224,000 243,000 258,000 259,000 265,000 245,000 256,000 260,000 239,000 241,000 282,000 329,000 310,000 340,000 458,000 669,000 996,000 1446,000 2329,000 2653,000 2365,000 1938,000 1402,000 954,000 597,000 421,000 366,000 357,000 316,000 318,000 301,000 284,000 270,000 279,000 237,000 253,000 237,000 223,000 227,000 210,000 210,000 234,000 211,000 222,000 262,000 243,000 223,000 220,000 213,000 215,000 216,000 210,000 226,000 247,000 227,000 207,000 236,000 242,000 229,000 194,000 240,000 212,000 245,000 226,000 231,000 213,000 216,000 207,000 233,000 225,000 220,000 251,000 204,000 238,000 217,000 221,000 232,000 213,000 202,000 237,000 210,000 192,000 246,000 226,000 242,000 237,000 211,000 222,000 214,000 219,000 219,000 233,000 231,000 228,000 226,000 194,000 217,000 228,000 210,000 229,000 222,000 211,000 209,000 214,000 201,000 233,000 221,000 197,000 220,000 212,000 200,000 213,000 214,000 210,000 211,000 192,000 189,000 220,000 210,000 190,000 213,000 209,000 210,000 201,000 223,000 196,000 182,000 205,000 194,000 200,000 187,000 193,000 197,000 205,000 213,000 216,000 211,000 198,000 250,000 214,000 188,000 234,000 190,000 193,000 212,000 179,000 189,000 232,000 169,000 197,000 200,000 209,000 216,000 221,000 175,000 199,000 191,000 221,000 183,000 177,000 178,000 198,000 187,000 172,000 184,000 231,000 196,000 192,000 179,000 217,000 179,000 191,000 214,000 204,000 189,000 186,000 191,000 181,000 186,000 170,000 188,000 155,000 177,000 203,000 182,000 178,000 193,000 179,000 175,000 181,000 174,000 164,000 168,000 172,000 162,000 166,000 177,000 178,000 150,000 174,000 142,000 157,000 174,000 173,000 153,000 169,000 166,000 166,000 162,000 157,000 174,000 161,000 178,000 173,000 169,000 168,000 177,000 163,000 168,000 172,000 175,000 193,000 162,000 167,000 178,000 172,000 160,000 172,000 171,000 182,000 129,000 152,000 151,000 166,000 163,000 163,000 168,000 164,000 161,000 184,000 180,000 170,000 167,000 155,000 169,000 158,000 154,000 163,000 141,000 148,000 146,000 168,000 136,000 157,000 153,000 155,000 148,000 157,000 196,000 180,000 215,000 177,000 173,000 183,000 155,000 173,000 140,000 137,000 149,000 159,000 162,000 172,000 148,000 157,000 161,000 137,000 141,000 153,000 146,000 179,000 154,000 155,000 133,000 191,000 165,000 170,000 173,000 187,000 220,000 229,000 256,000 278,000 287,000 353,000 395,000 342,000 427,000 447,000 420,000 463,000 544,000 612,000 815,000 1231,000 2068,000 3840,000 5708,000 8052,000 10343,000 11268,000 8129,000 5914,000 5612,000 3972,000 1686,000 883,000 630,000 526,000 477,000 437,000 418,000 380,000 344,000 259,000 270,000 254,000 215,000 208,000 193,000 175,000 184,000 188,000 194,000 147,000 157,000 177,000 172,000 168,000 145,000 154,000 140,000 146,000 163,000 132,000 145,000 136,000 154,000 155,000 149,000 198,000 176,000 203,000 211,000 210,000 207,000 206,000 187,000 155,000 120,000 139,000 131,000 144,000 114,000 107,000 110,000 112,000 100,000 123,000 126,000 137,000 117,000 107,000 138,000 113,000 105,000 114,000 125,000 134,000 97,000 105,000 130,000 132,000 123,000 112,000 144,000 117,000 129,000 143,000 111,000 113,000 112,000 107,000 114,000 140,000 120,000 116,000 106,000 109,000 116,000 120,000 105,000 106,000 108,000 122,000 101,000 126,000 131,000 121,000 123,000 108,000 103,000 99,000 105,000 112,000 119,000 97,000 113,000 117,000 116,000 122,000 128,000 114,000 117,000 104,000 99,000 108,000 94,000 114,000 125,000 114,000 107,000 87,000 125,000 114,000 111,000 124,000 93,000 112,000 111,000 82,000 111,000 130,000 113,000 112,000 105,000 104,000 109,000 106,000 128,000 118,000 105,000 112,000 115,000 105,000 120,000 106,000 111,000 103,000 101,000 117,000 99,000 98,000 92,000 116,000 104,000 118,000 107,000 105,000 107,000 102,000 116,000 91,000 115,000 111,000 118,000 95,000 102,000 118,000 109,000 100,000 114,000 108,000 92,000 108,000 91,000 123,000 101,000 107,000 93,000 100,000 114,000 102,000 109,000 89,000 88,000 94,000 99,000 111,000 113,000 97,000 100,000 88,000 112,000 96,000 78,000 101,000 109,000 104,000 88,000 97,000 134,000 112,000 108,000 95,000 97,000 102,000 81,000 104,000 99,000 112,000 96,000 87,000 113,000 85,000 98,000 100,000 113,000 100,000 101,000 106,000 112,000 94,000 104,000 88,000 85,000 101,000 104,000 60,000 91,000 78,000 107,000 108,000 97,000 92,000 87,000 90,000 96,000 94,000 88,000 92,000 102,000 91,000 94,000 101,000 79,000 87,000 102,000 86,000 97,000 95,000 97,000 91,000 98,000 95,000 93,000 91,000 95,000 92,000 81,000 81,000 103,000 98,000 80,000 93,000 85,000 91,000 93,000 95,000 106,000 93,000 106,000 90,000 91,000 101,000 84,000 114,000 97,000 85,000 80,000 79,000 75,000 86,000 104,000 94,000 101,000 100,000 107,000 78,000 84,000 118,000 101,000 102,000 90,000 92,000 94,000 87,000 93,000 96,000 87,000 108,000 74,000 91,000 92,000 80,000 82,000 103,000 85,000 79,000 103,000 75,000 84,000 94,000 104,000 84,000 94,000 76,000 95,000 94,000 92,000 111,000 89,000 113,000 90,000 90,000 93,000 74,000 86,000 86,000 100,000 81,000 80,000 94,000 95,000 102,000 105,000 101,000 99,000 98,000 101,000 106,000 85,000 73,000 104,000 85,000 95,000 96,000 82,000 92,000 92,000 89,000 93,000 82,000 92,000 83,000 90,000 94,000 88,000 105,000 92,000 93,000 98,000 97,000 74,000 103,000 94,000 84,000 97,000 102,000 80,000 71,000 92,000 97,000 88,000 89,000 75,000 89,000 87,000 84,000 93,000 81,000 81,000 96,000 79,000 74,000 77,000 87,000 87,000 93,000 89,000 106,000 74,000 107,000 104,000 84,000 86,000 95,000 77,000 98,000 85,000 100,000 103,000 105,000 98,000 103,000 91,000 102,000 65,000 103,000 100,000 86,000 69,000 92,000 93,000 92,000 86,000 104,000 106,000 90,000 96,000 70,000 98,000 84,000 84,000 93,000 92,000 72,000 91,000 96,000 87,000 83,000 98,000 78,000 88,000 85,000 111,000 80,000 78,000 89,000 89,000 85,000 75,000 104,000 92,000 112,000 99,000 94,000 78,000 97,000 87,000 81,000 83,000 85,000 74,000 80,000 79,000 96,000 79,000 109,000 89,000 83,000 71,000 84,000 86,000 93,000 94,000 74,000 95,000 115,000 77,000 89,000 87,000 90,000 84,000 115,000 74,000 75,000 90,000 91,000 95,000 101,000 89,000 110,000 104,000 107,000 120,000 95,000 139,000 164,000 162,000 250,000 396,000 524,000 695,000 756,000 671,000 557,000 435,000 418,000 422,000 355,000 216,000 155,000 135,000 111,000 96,000 102,000 103,000 85,000 85,000 92,000 85,000 94,000 80,000 88,000 93,000 75,000 96,000 95,000 95,000 82,000 87,000 73,000 96,000 90,000 86,000 99,000 81,000 69,000 80,000 80,000 80,000 82,000 82,000 80,000 70,000 63,000 91,000 80,000 68,000 83,000 74,000 73,000 74,000 84,000 87,000 82,000 88,000 81,000 93,000 73,000 72,000 84,000 88,000 75,000 104,000 89,000 84,000 89,000 75,000 90,000 77,000 79,000 79,000 77,000 71,000 83,000 69,000 73,000 95,000 80,000 86,000 84,000 74,000 93,000 76,000 67,000 73,000 88,000 76,000 59,000 65,000 74,000 67,000 68,000 81,000 81,000 83,000 84,000 81,000 94,000 81,000 61,000 75,000 87,000 88,000 83,000 80,000 82,000 80,000 83,000 80,000 70,000 86,000 72,000 80,000 65,000 78,000 78,000 74,000 59,000 84,000 65,000 73,000 83,000 66,000 104,000 85,000 72,000 73,000 79,000 93,000 87,000 76,000 87,000 95,000 88,000 90,000 93,000 73,000 102,000 106,000 106,000 110,000 118,000 144,000 187,000 255,000 348,000 481,000 558,000 643,000 434,000 314,000 300,000 361,000 327,000 272,000 180,000 119,000 111,000 81,000 106,000 96,000 82,000 73,000 93,000 80,000 88,000 75,000 85,000 80,000 90,000 74,000 72,000 79,000 75,000 89,000 95,000 86,000 77,000 92,000 93,000 97,000 110,000 92,000 123,000 151,000 209,000 287,000 357,000 434,000 393,000 272,000 248,000 218,000 273,000 245,000 202,000 145,000 107,000 101,000 83,000 88,000 83,000 79,000 77,000 84,000 85,000 69,000 77,000 70,000 67,000 91,000 66,000 66,000 86,000 73,000 54,000 64,000 76,000 77,000 55,000 67,000 68,000 68,000 74,000 82,000 74,000 58,000 70,000 65,000 72,000 68,000 64,000 80,000 73,000 63,000 76,000 76,000 81,000 90,000 70,000 70,000 81,000 70,000 81,000 76,000 72,000 79,000 72,000 72,000 75,000 73,000 73,000 65,000 72,000 76,000 78,000 68,000 83,000 84,000 70,000 80,000 69,000 86,000 76,000 62,000 78,000 77,000 86,000 97,000 82,000 72,000 74,000 73,000 89,000 75,000 70,000 81,000 89,000 79,000 72,000 77,000 84,000 74,000 91,000 77,000 91,000 86,000 93,000 111,000 98,000 115,000 140,000 157,000 223,000 293,000 420,000 487,000 410,000 329,000 245,000 273,000 292,000 291,000 229,000 163,000 117,000 103,000 89,000 104,000 96,000 90,000 83,000 101,000 81,000 72,000 73,000 84,000 104,000 71,000 93,000 71,000 68,000 79,000 83,000 84,000 72,000 79,000 82,000 67,000 77,000 86,000 87,000 72,000 66,000 76,000 84,000 73,000 93,000 90,000 74,000 68,000 84,000 64,000 75,000 66,000 84,000 81,000 77,000 68,000 95,000 62,000 88,000 73,000 69,000 82,000 49,000 68,000 78,000 75,000 74,000 92,000 85,000 80,000 74,000 85,000 90,000 65,000 80,000 68,000 83,000 60,000 63,000 81,000 83,000 84,000 98,000 87,000 84,000 84,000 91,000 74,000 89,000 82,000 71,000 82,000 91,000 98,000 90,000 77,000 83,000 77,000 76,000 75,000 67,000 73,000 83,000 82,000 62,000 76,000 75,000 65,000 76,000 66,000 78,000 88,000 82,000 67,000 97,000 68,000 95,000 72,000 76,000 74,000 81,000 81,000 60,000 77,000 74,000 60,000 80,000 85,000 85,000 65,000 67,000 75,000 90,000 80,000 73,000 78,000 79,000 85,000 91,000 87,000 107,000 81,000 82,000 78,000 87,000 77,000 87,000 86,000 82,000 77,000 94,000 69,000 97,000 74,000 78,000 91,000 79,000 78,000 79,000 77,000 92,000 95,000 91,000 95,000 107,000 105,000 146,000 164,000 227,000 282,000 339,000 296,000 256,000 206,000 192,000 220,000 200,000 184,000 154,000 133,000 83,000 94,000 98,000 89,000 94,000 87,000 84,000 78,000 96,000 84,000 80,000 91,000 85,000 78,000 97,000 70,000 80,000 74,000 79,000 83,000 78,000 83,000 90,000 76,000 73,000 75,000 81,000 68,000 79,000 64,000 86,000 94,000 72,000 78,000 88,000 73,000 81,000 80,000 75,000 70,000 70,000 61,000 71,000 69,000 81,000 71,000 74,000 53,000 69,000 72,000 69,000 76,000 62,000 72,000 83,000 63,000 77,000 79,000 74,000 81,000 86,000 76,000 75,000 58,000 89,000 83,000 62,000 64,000 65,000 69,000 68,000 62,000 78,000 79,000 104,000 79,000 93,000 78,000 78,000 91,000 67,000 67,000 73,000 65,000 69,000 80,000 88,000 66,000 78,000 70,000 85,000 78,000 69,000 80,000 71,000 70,000 71,000 85,000 81,000 79,000 82,000 70,000 81,000 69,000 66,000 74,000 78,000 78,000 78,000 67,000 77,000 61,000 65,000 90,000 75,000 78,000 73,000 87,000 72,000 51,000 70,000 61,000 83,000 81,000 84,000 70,000 71,000 71,000 76,000 62,000 87,000 62,000 66,000 77,000 76,000 80,000 68,000 83,000 69,000 72,000 70,000 79,000 74,000 65,000 77,000 79,000 100,000 76,000 80,000 69,000 65,000 70,000 61,000 80,000 70,000 84,000 75,000 62,000 89,000 68,000 73,000 76,000 70,000 82,000 74,000 65,000 63,000 80,000 70,000 64,000 73,000 73,000 76,000 63,000 78,000 65,000 76,000 70,000 67,000 75,000 71,000 87,000 83,000 70,000 76,000 78,000 66,000 80,000 66,000 84,000 76,000 90,000 94,000 103,000 111,000 116,000 118,000 119,000 145,000 130,000 155,000 161,000 209,000 290,000 481,000 785,000 1159,000 1442,000 1483,000 1021,000 697,000 527,000 615,000 835,000 836,000 813,000 528,000 345,000 219,000 188,000 158,000 142,000 113,000 122,000 115,000 83,000 87,000 103,000 90,000 94,000 110,000 99,000 105,000 103,000 115,000 94,000 72,000 74,000 87,000 96,000 95,000 74,000 72,000 83,000 76,000 85,000 72,000 84,000 70,000 55,000 66,000 76,000 77,000 82,000 61,000 68,000 83,000 61,000 83,000 77,000 77,000 70,000 54,000 73,000 84,000 72,000 68,000 62,000 74,000 78,000 66,000 70,000 81,000 58,000 69,000 60,000 60,000 66,000 75,000 85,000 82,000 55,000 65,000 70,000 66,000 70,000 76,000 63,000 66,000 62,000 71,000 67,000 67,000 65,000 76,000 85,000 68,000 88,000 61,000 74,000 76,000 78,000 74,000 70,000 60,000 56,000 57,000 57,000 75,000 83,000 79,000 79,000 71,000 85,000 71,000 73,000 63,000 74,000 74,000 83,000 62,000 79,000 57,000 76,000 60,000 53,000 66,000 67,000 72,000 72,000 67,000 75,000 70,000 68,000 60,000 72,000 76,000 63,000 69,000 85,000 68,000 68,000 65,000 84,000 63,000 78,000 63,000 67,000 60,000 66,000 90,000 71,000 65,000 59,000 63,000 65,000 65,000 63,000 71,000 77,000 85,000 67,000 64,000 72,000 63,000 65,000 67,000 80,000 81,000 55,000 63,000 68,000 68,000 65,000 65,000 57,000 71,000 55,000 75,000 74,000 64,000 64,000 74,000 75,000 52,000 59,000 53,000 59,000 56,000 76,000 52,000 59,000 71,000 77,000 69,000 89,000 77,000 79,000 53,000 72,000 59,000 66,000 68,000 66,000 69,000 70,000 64,000 76,000 64,000 81,000 66,000 67,000 62,000 73,000 77,000 59,000 63,000 62,000 67,000 79,000 64,000 70,000 99,000 76,000 84,000 72,000 69,000 66,000 77,000 70,000 88,000 57,000 90,000 81,000 86,000 73,000 103,000 89,000 123,000 117,000 161,000 183,000 246,000 287,000 333,000 313,000 288,000 213,000 189,000 171,000 197,000 173,000 218,000 198,000 173,000 140,000 105,000 85,000 96,000 78,000 102,000 90,000 103,000 116,000 105,000 115,000 129,000 156,000 154,000 158,000 133,000 117,000 110,000 120,000 113,000 125,000 111,000 86,000 95,000 65,000 70,000 71,000 76,000 72,000 78,000 71,000 71,000 71,000 72,000 71,000 74,000 57,000 66,000 77,000 68,000 77,000 79,000 74,000 70,000 71,000 72,000 66,000 65,000 54,000 66,000 79,000 71,000 62,000 78,000 82,000 83,000 73,000 60,000 76,000 61,000 48,000 78,000 74,000 59,000 69,000 73,000 69,000 79,000 79,000 74,000 71,000 55,000 79,000 68,000 84,000 71,000 80,000 74,000 67,000 84,000 65,000 60,000 96,000 68,000 61,000 66,000 88,000 68,000 61,000 67,000 70,000 73,000 78,000 81,000 72,000 75,000 67,000 80,000 79,000 68,000 53,000 73,000 87,000 62,000 82,000 85,000 92,000 90,000 88,000 59,000 70,000 63,000 70,000 88,000 65,000 72,000 79,000 58,000 75,000 72,000 86,000 71,000 67,000 72,000 71,000 65,000 79,000 86,000 70,000 79,000 79,000 63,000 63,000 74,000 86,000 70,000 67,000 71,000 77,000 72,000 68,000 65,000 75,000 63,000 62,000 69,000 62,000 60,000 62,000 69,000 59,000 74,000 87,000 86,000 69,000 64,000 72,000 75,000 93,000 58,000 58,000 67,000 64,000 59,000 72,000 72,000 83,000 70,000 69,000 77,000 65,000 66,000 74,000 71,000 83,000 91,000 91,000 89,000 99,000 88,000 69,000 73,000 70,000 80,000 69,000 68,000 87,000 72,000 74,000 68,000 62,000 57,000 84,000 74,000 75,000 67,000 68,000 68,000 79,000 66,000 78,000 72,000 89,000 81,000 73,000 75,000 79,000 71,000 65,000 55,000 68,000 63,000 67,000 61,000 73,000 56,000 80,000 81,000 76,000 77,000 82,000 67,000 66,000 72,000 79,000 75,000 91,000 99,000 100,000 108,000 98,000 106,000 104,000 108,000 119,000 144,000 138,000 134,000 197,000 251,000 359,000 426,000 599,000 706,000 744,000 579,000 439,000 316,000 294,000 301,000 362,000 400,000 431,000 361,000 307,000 232,000 144,000 112,000 104,000 111,000 92,000 87,000 77,000 74,000 102,000 93,000 77,000 73,000 94,000 59,000 80,000 75,000 68,000 76,000 73,000 81,000 72,000 90,000 86,000 81,000 89,000 70,000 83,000 79,000 66,000 76,000 75,000 73,000 56,000 69,000 79,000 51,000 82,000 62,000 65,000 66,000 78,000 75,000 71,000 72,000 72,000 91,000 85,000 60,000 64,000 65,000 72,000 61,000 67,000 70,000 62,000 65,000 80,000 81,000 67,000 98,000 68,000 66,000 68,000 89,000 58,000 83,000 77,000 72,000 57,000 65,000 77,000 69,000 71,000 82,000 66,000 67,000 68,000 77,000 75,000 78,000 72,000 80,000 65,000 78,000 95,000 84,000 76,000 75,000 78,000 62,000 69,000 68,000 64,000 82,000 69,000 68,000 84,000 91,000 56,000 62,000 79,000 58,000 70,000 71,000 78,000 70,000 71,000 71,000 72,000 64,000 73,000 65,000 77,000 68,000 85,000 79,000 73,000 60,000 59,000 65,000 58,000 72,000 74,000 73,000 56,000 62,000 73,000 72,000 65,000 83,000 72,000 53,000 80,000 78,000 71,000 66,000 84,000 62,000 66,000 74,000 86,000 77,000 80,000 77,000 61,000 63,000 87,000 63,000 71,000 65,000 86,000 70,000 63,000 80,000 65,000 69,000 66,000 64,000 71,000 71,000 88,000 71,000 74,000 67,000 74,000 63,000 70,000 92,000 70,000 68,000 63,000 73,000 86,000 77,000 70,000 81,000 88,000 73,000 77,000 79,000 82,000 80,000 69,000 88,000 70,000 79,000 101,000 148,000 202,000 261,000 254,000 223,000 194,000 168,000 103,000 131,000 137,000 147,000 173,000 176,000 159,000 135,000 115,000 100,000 91,000 72,000 60,000 75,000 79,000 79,000 66,000 73,000 62,000 88,000 80,000 72,000 79,000 67,000 75,000 73,000 86,000 62,000 78,000 62,000 84,000 70,000 81,000 75,000 64,000 69,000 67,000 67,000 73,000 71,000 81,000 70,000 50,000 58,000 65,000 66,000 66,000 81,000 75,000 84,000 55,000 77,000 88,000 78,000 75,000 76,000 70,000 68,000 72,000 72,000 70,000 66,000 79,000 59,000 63,000 71,000 64,000 86,000 67,000 76,000 65,000 77,000 88,000 76,000 60,000 67,000 79,000 72,000 74,000 74,000 78,000 73,000 73,000 92,000 100,000 93,000 91,000 74,000 75,000 87,000 72,000 82,000 87,000 76,000 87,000 97,000 79,000 62,000 72,000 72,000 61,000 72,000 78,000 72,000 88,000 72,000 79,000 60,000 61,000 67,000 75,000 71,000 77,000 82,000 76,000 69,000 60,000 83,000 75,000 93,000 77,000 78,000 56,000 66,000 75,000 62,000 77,000 54,000 70,000 67,000 55,000 56,000 62,000 75,000 54,000 60,000 64,000 65,000 63,000 76,000 80,000 70,000 73,000 69,000 80,000 70,000 80,000 61,000 68,000 68,000 72,000 75,000 70,000 88,000 70,000 70,000 92,000 70,000 66,000 88,000 85,000 73,000 79,000 84,000 76,000 67,000 73,000 101,000 78,000 87,000 101,000 91,000 96,000 96,000 115,000 117,000 142,000 183,000 206,000 263,000 297,000 362,000 364,000 383,000 340,000 264,000 216,000 188,000 200,000 198,000 260,000 251,000 284,000 274,000 223,000 218,000 171,000 222,000 241,000 280,000 424,000 461,000 558,000 569,000 498,000 415,000 309,000 342,000 346,000 371,000 414,000 534,000 620,000 584,000 453,000 318,000 228,000 209,000 204,000 225,000 217,000 237,000 229,000 166,000 154,000 139,000 96,000 99,000 105,000 82,000 86,000 82,000 77,000 92,000 72,000 77,000 77,000 89,000 83,000 80,000 72,000 57,000 83,000 86,000 72,000 89,000 77,000 67,000 72,000 79,000 74,000 77,000 78,000 62,000 84,000 75,000 61,000 61,000 76,000 69,000 59,000 67,000 50,000 59,000 45,000 62,000 65,000 74,000 73,000 74,000 73,000 70,000 71,000 72,000 82,000 65,000 76,000 73,000 83,000 68,000 79,000 64,000 50,000 71,000 83,000 62,000 75,000 73,000 83,000 63,000 70,000 68,000 68,000 76,000 67,000 62,000 61,000 60,000 74,000 62,000 94,000 76,000 60,000 70,000 78,000 62,000 70,000 67,000 72,000 65,000 81,000 66,000 56,000 65,000 63,000 52,000 76,000 69,000 69,000 71,000 67,000 75,000 75,000 47,000 71,000 55,000 82,000 58,000 61,000 64,000 80,000 88,000 61,000 68,000 64,000 56,000 69,000 69,000 70,000 66,000 88,000 62,000 64,000 51,000 85,000 86,000 60,000 78,000 57,000 84,000 72,000 80,000 61,000 44,000 60,000 51,000 70,000 73,000 61,000 74,000 65,000 79,000 61,000 71,000 62,000 65,000 65,000 54,000 73,000 69,000 64,000 67,000 75,000 68,000 75,000 51,000 81,000 63,000 57,000 72,000 76,000 57,000 70,000 67,000 54,000 83,000 73,000 57,000 52,000 83,000 85,000 56,000 73,000 69,000 60,000 85,000 52,000 71,000 65,000 60,000 55,000 72,000 71,000 75,000 59,000 72,000 73,000 61,000 55,000 77,000 81,000 62,000 76,000 68,000 66,000 68,000 62,000 64,000 70,000 79,000 61,000 76,000 62,000 84,000 71,000 84,000 72,000 58,000 81,000 67,000 71,000 68,000 85,000 53,000 76,000 81,000 74,000 60,000 71,000 63,000 62,000 66,000 63,000 62,000 67,000 72,000 55,000 76,000 73,000 59,000 72,000 67,000 73,000 65,000 67,000 72,000 59,000 74,000 81,000 82,000 83,000 85,000 105,000 123,000 104,000 141,000 143,000 171,000 221,000 236,000 237,000 201,000 133,000 147,000 101,000 96,000 100,000 137,000 120,000 147,000 164,000 127,000 131,000 119,000 84,000 75,000 84,000 78,000 77,000 55,000 69,000 63,000 68,000 71,000 62,000 74,000 72,000 58,000 63,000 64,000 80,000 68,000 66,000 56,000 91,000 69,000 86,000 70,000 63,000 84,000 72,000 65,000 66,000 64,000 68,000 66,000 73,000 64,000 58,000 77,000 56,000 56,000 63,000 64,000 68,000 75,000 75,000 71,000 83,000 70,000 71,000 65,000 65,000 79,000 65,000 71,000 84,000 81,000 61</intensities>
      </dataPoints>
    </scan>
  </xrdMeasurement>
</xrdMeasurements>